# Error Handling in Rust

## Learning Objectives
- Understand Rust's error handling philosophy and methods
- Learn about unrecoverable errors and the use of the `panic!` macro
- Study recoverable error handling using the `Result<T, E>` type
- Master error propagation techniques and the usage of the `?` operator
- Understand when to use `panic!` versus when to return `Result`
- Learn how to create custom error types

## Rust's Error Handling Philosophy

Rust, as a language that prioritizes safety and reliability, takes a clear and systematic approach to error handling. Rust's error handling system is divided into two main categories:

1. Unrecoverable Errors
2. Recoverable Errors

This distinction allows programmers to clearly understand the nature of errors and choose appropriate handling methods.

## Unrecoverable Errors and `panic!`

Unrecoverable errors represent serious situations where a program cannot continue normal execution. In Rust, these situations are handled using the `panic!` macro.

### How `panic!` Works

When `panic!` occurs, the following process takes place:

1. Error message output
2. Stack unwinding or immediate abort
3. Program termination

```rust
fn main() {
    panic!("crash and burn");
}
```

Running this code will produce output like:

```
thread 'main' panicked at 'crash and burn', src/main.rs:2:5
note: Run with `RUST_BACKTRACE=1` environment variable to display a backtrace.
```

### Using Backtrace

You can get more detailed information when `panic!` occurs by setting the `RUST_BACKTRACE` environment variable:

```bash
$ RUST_BACKTRACE=1 cargo run
```

This is very useful during debugging.

### When to Use `panic!`

`panic!` is typically used in the following situations:

1. Errors that should never occur
2. Unexpected behavior from external code
3. Situations where further error handling is impossible

```rust
fn main() {
    let v = vec![1, 2, 3];
    v[99]; // This line will cause a panic!
}
```

## Recoverable Errors and `Result<T, E>`

Recoverable errors are errors that can be handled without disrupting the normal execution of the program. Rust handles these using the `Result<T, E>` enum.

### The `Result<T, E>` Type

`Result<T, E>` is defined as:

```rust
enum Result<T, E> {
    Ok(T),
    Err(E),
}
```

Here, `T` is the type of value returned on success, and `E` is the type of error returned on failure.

### Example Using `Result`

Let's look at a simple example of using `Result` to open a file and read its contents:

```rust
use std::fs::File;
use std::io::Read;

fn read_username_from_file() -> Result<String, std::io::Error> {
    let mut username = String::new();
    File::open("hello.txt")?.read_to_string(&mut username)?;
    Ok(username)
}

fn main() {
    match read_username_from_file() {
        Ok(username) => println!("Username: {}", username),
        Err(e) => println!("Error: {}", e),
    }
}
```

In this example, the `?` operator allows for easy error propagation in functions that return `Result`.

### `unwrap` and `expect`

The `unwrap` and `expect` methods of `Result` either return the `Ok` value or cause a `panic!`:

```rust
let f = File::open("hello.txt").unwrap();
let f = File::open("hello.txt").expect("Failed to open hello.txt");
```

These methods are primarily used in prototyping or testing, while more fine-grained error handling is recommended for production code.

## Error Propagation

Error propagation refers to passing errors up to the calling function. In Rust, this can be done easily using the `?` operator.

### The `?` Operator

The `?` operator is used after expressions that return `Result` and works as follows:

1. If the result is `Ok`, extract the value inside `Ok`
2. If the result is `Err`, immediately return that `Err`

```rust
fn read_username_from_file() -> Result<String, std::io::Error> {
    let mut file = File::open("hello.txt")?;
    let mut username = String::new();
    file.read_to_string(&mut username)?;
    Ok(username)
}
```

### Chaining Method Calls

The `?` operator allows for chaining multiple operations:

```rust
fn read_username_from_file() -> Result<String, std::io::Error> {
    let mut username = String::new();
    File::open("hello.txt")?.read_to_string(&mut username)?;
    Ok(username)
}
```

This approach makes the code more concise and readable.

## To `panic!` or to `Result`

Deciding whether to use `panic!` or return `Result` is an important design decision. Here are some guidelines:

### When to Use `panic!`

1. In examples, prototypes, and tests
2. In unrecoverable situations
3. When continuing execution could cause security issues due to invalid values

### When to Use `Result`

1. In expected error situations
2. When the caller can recover from or handle the error
3. When designing library APIs

```rust
pub struct Guess {
    value: i32,
}

impl Guess {
    pub fn new(value: i32) -> Result<Guess, String> {
        if value < 1 || value > 100 {
            Err(String::from("Guess value must be between 1 and 100"))
        } else {
            Ok(Guess { value })
        }
    }

    pub fn value(&self) -> i32 {
        self.value
    }
}
```

## Custom Error Types

In complex applications, creating custom error types can be useful. This enables more specific and meaningful error handling.

```rust
use std::fmt;
use std::error::Error;

#[derive(Debug)]
pub enum AppError {
    IoError(std::io::Error),
    ParseError(std::num::ParseIntError),
    CustomError(String),
}

impl fmt::Display for AppError {
    fn fmt(&self, f: &mut fmt::Formatter) -> fmt::Result {
        match self {
            AppError::IoError(e) => write!(f, "IO error: {}", e),
            AppError::ParseError(e) => write!(f, "Parse error: {}", e),
            AppError::CustomError(s) => write!(f, "Custom error: {}", s),
        }
    }
}

impl Error for AppError {}

impl From<std::io::Error> for AppError {
    fn from(error: std::io::Error) -> Self {
        AppError::IoError(error)
    }
}

impl From<std::num::ParseIntError> for AppError {
    fn from(error: std::num::ParseIntError) -> Self {
        AppError::ParseError(error)
    }
}
```

## Advanced Error Handling Techniques

Rust's error handling system provides various advanced techniques beyond basic usage. These enable effective error handling in more complex situations.

### 1. Handling Multiple Error Types

When dealing with multiple types of errors, you can use `Box<dyn Error>` to unify various error types:

```rust
use std::error::Error;
use std::fs::File;
use std::io::Read;

fn read_and_parse() -> Result<i32, Box<dyn Error>> {
    let mut file = File::open("number.txt")?;
    let mut contents = String::new();
    file.read_to_string(&mut contents)?;
    let number: i32 = contents.trim().parse()?;
    Ok(number)
}
```

### 2. Using the `thiserror` Crate

The `thiserror` crate makes it easier to create custom error types:

```rust
use thiserror::Error;

#[derive(Error, Debug)]
pub enum DataStoreError {
    #[error("data not found")]
    NotFound(String),
    #[error("invalid data: {0}")]
    InvalidData(String),
    #[error("I/O error")]
    Io(#[from] std::io::Error),
}
```

### 3. Simplifying Error Handling with `anyhow`

The `anyhow` crate simplifies error handling, particularly in application code:

```rust
use anyhow::{Context, Result};
use std::fs::File;
use std::io::Read;

fn read_config() -> Result<String> {
    let mut file = File::open("config.txt")
        .with_context(|| "Failed to open config file")?;
    let mut contents = String::new();
    file.read_to_string(&mut contents)
        .with_context(|| "Failed to read config file")?;
    Ok(contents)
}
```

The `anyhow::Result` can handle any error type, and `with_context` provides additional context information.

The Context trait:
```rust
pub trait Context<T, E>: Sized {
    fn with_context<C, F>(self, f: F) -> Result<T, Error>
    where
        C: Display + Send + Sync + 'static,
        F: FnOnce() -> C;
}
```

Implementation of the Context trait:
```rust
impl<T, E> Context<T, E> for Result<T, E>
where
    E: std::error::Error + Send + Sync + 'static,
{
    fn with_context<C, F>(self, f: F) -> Result<T, Error>
    where
        C: Display + Send + Sync + 'static,
        F: FnOnce() -> C,
    {
        self.map_err(|error| {
            let context = f();
            anyhow::Error::new(error).context(context)
        })
    }
}
```

### 4. Error Conversion

Sometimes you need to convert one error type to another. In Rust, this can be done by implementing the `From` trait:

```rust
#[derive(Debug)]
pub enum AppError {
    IoError(std::io::Error),
    ParseError(std::num::ParseIntError),
}

impl From<std::io::Error> for AppError {
    fn from(error: std::io::Error) -> Self {
        AppError::IoError(error)
    }
}

impl From<std::num::ParseIntError> for AppError {
    fn from(error: std::num::ParseIntError) -> Self {
        AppError::ParseError(error)
    }
}

fn read_and_parse() -> Result<i32, AppError> {
    let mut file = File::open("number.txt")?;
    let mut contents = String::new();
    file.read_to_string(&mut contents)?;
    let number: i32 = contents.trim().parse()?;
    Ok(number)
}
```

## Practice in VSCode

1. Open VSCode and create a new Rust project: `cargo new rust_error_handling`
2. Write the following code in `src/main.rs`:

```rust
use std::fs::File;
use std::io::Read;

fn read_username_from_file() -> Result<String, std::io::Error> {
    let mut username = String::new();
    File::open("hello.txt")?.read_to_string(&mut username)?;
    Ok(username)
}

fn main() {
    match read_username_from_file() {
        Ok(username) => println!("Username: {}", username),
        Err(e) => println!("Error: {}", e),
    }

    // panic! example
    // let v = vec![1, 2, 3];
    // v[99];
}
```

3. Compile and run the code using `cargo run` in the terminal.

## Test Code

Here's test code to verify that the example code works correctly:

```rust
#[cfg(test)]
mod tests {
    use super::*;
    use std::io::Write;

    #[test]
    fn test_read_username_from_file() {
        // Create test file
        let mut file = File::create("test_hello.txt").unwrap();
        file.write_all(b"test_username").unwrap();

        // Test function
        let result = read_username_from_file();
        assert!(result.is_ok());
        assert_eq!(result.unwrap(), "test_username");

        // Delete test file
        std::fs::remove_file("test_hello.txt").unwrap();
    }

    #[test]
    #[should_panic(expected = "index out of bounds")]
    fn test_panic() {
        let v = vec![1, 2, 3];
        let _ = v[99];
    }
}
```

Add this test code at the end of `src/main.rs` and run tests using `cargo test`.

## References

1. Rust Official Documentation - Error Handling: https://doc.rust-lang.org/book/ch09-00-error-handling.html
2. Rust by Example - Error Handling: https://doc.rust-lang.org/rust-by-example/error.html
3. The Rust Programming Language (2nd Edition) by Steve Klabnik and Carol Nichols
4. Programming Rust (2nd Edition) by Jim Blandy, Jason Orendorff, and Leonora F. S. Tindall
5. Rust Official Documentation - std::error module: https://doc.rust-lang.org/std/error/index.html
6. `thiserror` crate documentation: [https://docs.rs/thiserror](https://docs.rs/thiserror)
7. `anyhow` crate documentation: [https://docs.rs/anyhow](https://docs.rs/anyhow)
8. Rust Error Handling Best Practices blog post: [https://nick.groenen.me/posts/rust-error-handling/](https://nick.groenen.me/posts/rust-error-handling/)